error: package directory 'py_drive' does not exist
